<mujoco model="humanoid">

  <statistic extent="2" center="0 0 1"/>

  <option timestep="0.00555"/>

  <default>
    <motor ctrlrange="-1 1" ctrllimited="true"/>
    <default class="body">
      <geom type="capsule" condim="1" friction="1.0 0.05 0.05" solimp=".9 .99 .003" solref=".015 1"/>
      <joint type="hinge" damping="0.1" stiffness="5" armature=".007" limited="true" solimplimit="0 .99 .01"/>
      <site size=".04" group="3"/>
      <default class="force-torque">
        <site type="box" size=".01 .01 .02" rgba="1 0 0 1" />
      </default>
      <default class="touch">
        <site type="capsule" rgba="0 0 1 .3"/>
      </default>
    </default>
  </default>

  <worldbody>
    <geom name="floor" type="plane" conaffinity="1" size="100 100 .2"/>
    <body name="pelvis" pos="0 0 1" childclass="body">
      <freejoint name="root"/>
      <site name="root" class="force-torque"/>
      <geom name="pelvis" fromto="0 0 -0.06 -1 0 -0" size=".19" density="2226"/>
      <geom name="upper_waist" type="sphere" pos="0 0 0.205" size="0.07" density="2226"/>
      <site name="pelvis" class="touch" type="sphere" pos="0 0 0.07" size="0.091"/>
      <site name="upper_waist" class="touch" type="sphere" pos="0 0 0.205" size="0.071"/>
	 <body name="head" pos="7.92815 1.03427 -0.957866">
          <joint name="neck_x" axis="1 0 0" range="-50 50" stiffness="100" damping="10" armature=".01"/>
          <joint name="neck_y" axis="0 1 0" range="-40 60" stiffness="100" damping="10" armature=".01"/>
          <joint name="neck_z" axis="0 0 1" range="-45 45" stiffness="100" damping="10" armature=".01"/>
          <geom name="head" type="sphere" pos="0 0 0.175" size="0.095" density="1081"/>
          <site name="head" class="touch" pos="0 0 0.175" type="sphere" size="0.103"/>
          <camera name="egocentric" pos=".103 0 0.175" xyaxes="0 -1 0 .1 0 1" fovy="80"/>
        </body>
         
         <body name="head1" pos="0 0 0.223894">
          <geom name="head1" type="sphere" pos="0 0 0.175" size="0.095" density="1081"/>
          <site name="head1" class="touch" pos="0 0 0.175" type="sphere" size="0.103"/>
          <camera name="egocentric1" pos=".103 0 0.175" xyaxes="0 -1 0 .1 0 1" fovy="80"/>
        </body>
        
    </body>
  </worldbody>

  <actuator>
  </actuator>

  <sensor>
  </sensor>

</mujoco>
